<?xml version="1.0"?>
<!-- #################################### -->
<!-- DESCRIPTION OF THE 4-WHEELED ROBOT   -->
<!-- Made by Aleksander Harber     -->
<!-- Aug 2025 -->
<!-- ####################################  -->

<robot name="differential_drive_robot" xmlns:xacro="http://www.ros.org/wiki/xacro">

<!-- Body dimensions -->
<xacro:property name="body_link_x_dim" value="1"/>
<xacro:property name="body_link_y_dim" value="0.6"/>
<xacro:property name="body_link_z_dim" value="0.3"/>

<!-- wheel dimensions -->
<xacro:property name="wheel_link_radius" value="0.15"/>
<xacro:property name="wheel_link_length" value="0.1"/>
<xacro:property name="wheel_link_z_location" value="${-body_link_z_dim/2 + wheel_link_radius}"/>

<!-- Material density -->
<xacro:property name="body_density" value="2710.0"/>
<xacro:property name="wheel_density" value="2710.0"/>

<!-- pi constant -->
<xacro:property name="pi_const" value="3.14159265"/>

<!-- Robot body and Wheel mass -->
<xacro:property name="body_mass"
value="${body_density*body_link_x_dim*body_link_y_dim*body_link_z_dim}"/>

<xacro:property name="wheel_mass"
value="${wheel_density*pi_const*wheel_link_radius*wheel_link_radius*wheel_link_length}"/>

<!-- Moment of inertia of the wheel -->
<xacro:property name="Iz_wheel" value="${0.5*wheel_mass*wheel_link_radius*wheel_link_radius}" />
<xacro:property name="I_wheel" 
value="${(1.0/12.0)*wheel_mass*(3.0*wheel_link_radius+wheel_link_length*wheel_link_length)}" />

<!-- This macro defines the complete inertial section of the wheel -->
<!-- it is used in the code -->
<xacro:macro name="inertia_wheel">
	<inertial>
	<origin rpy="0 0 0"/>
	<mass value="${wheel_mass}"/>
	<inertia ixx="${I_wheel}" ixy="0.0" ixz="0.0" iyy="${I_wheel}" iyz="0" izz="${Iz_wheel}" />
	</inertial>
</xacro:macro>


<!-- over here we included the file that define extra gazebo options and motion control driver -->
<xacro:include filename="$(find mobile_robot)/model/robot.gazebo" />

<!-- ########################################### -->
<!-- FROM HERE WE DEFINE LINKS,JOINTS     -->
<!-- ###########################################-->

<!-- We need to have this dummy link otherwise gazebo will complain -->
<link name="dummy">
</link>
<joint name="dummy_joint" type="fixed">
	<parent link="dummy"/>
	<child link="body_link"/>
</joint>

<!-- ########################################### -->
<!-- START: Body link of the robot  -->
<!-- ########################################### -->
<link name="body_link">
	<visual>
		<geometry>
			<box size="${body_link_x_dim} ${body_link_y_dim} ${body_link_z_dim}" />
		</geometry>
	<origin rpy="0 0 0" xyz="0 0 0"/>
	</visual>
	
	<collision>
		<geometry>
			<box size="${body_link_x_dim} ${body_link_y_dim} ${body_link_z_dim}"/>
		</geometry>
		<origin rpy="0 0 0" xyz="0 0 0"/>
	</collision>
	
	<inertial>
		<origin rpy="0 0 0" xyz="0 0 0"/>
		<mass value="${body_mass}"/>
	<inertia
  		ixx="${(1.0/12.0)*body_mass*(body_link_y_dim*body_link_y_dim + body_link_z_dim*body_link_z_dim)}"
  		iyy="${(1.0/12.0)*body_mass*(body_link_x_dim*body_link_x_dim + body_link_z_dim*body_link_z_dim)}"
  		izz="${(1.0/12.0)*body_mass*(body_link_x_dim*body_link_x_dim + body_link_y_dim*body_link_y_dim)}"
  		ixy="0" ixz="0" iyz="0"/>

	</inertial>
</link>

<!-- ################################################# -->
<!-- END: Body link of the robot -->
<!-- ################################################# -->


<!-- ################################################# -->
<!-- START: Back right wheel of the robot and the joint -->
<!-- ################################################# -->

<joint name="wheel1_joint" type="continuous" >
	<parent link="body_link"/>
	<child  link="wheel1_link" />
	<origin xyz="${-body_link_x_dim/2+1.2*wheel_link_radius} ${-body_link_y_dim/2-wheel_link_length/2} ${wheel_link_z_location}" rpy="0 0 0" />
	<axis xyz="0 1 0"/>
	<limit effort="1000" velocity="1000"/>
	<dynamics damping="1.0" friction="1.0"/>
</joint>

<link name="wheel1_link">
	<visual>
		<origin rpy="1.570795 0 0" xyz="0 0 0"/>
		<geometry>
			<cylinder length="${wheel_link_length}" radius="${wheel_link_radius}"/>
		</geometry>
	</visual>
	
	<collision>
		<origin rpy="1.570795 0 0" xyz="0 0 0"/>
		<geometry>
			<cylinder length="${wheel_link_length}" radius="${wheel_link_radius}"/>	
		</geometry>
	</collision>
	
	<xacro:inertia_wheel />
</link>

<!-- ################################################# -->
<!-- END: back right wheel of the robot and the joint -->
<!-- ################################################# -->




<!-- ################################################# -->
<!-- START: back left wheel of the robot and the joint -->
<!-- ################################################# -->

<joint name="wheel2_joint" type="continuous" >
	<parent link="body_link"/>
	<child  link="wheel2_link" />
	<origin xyz="${-body_link_x_dim/2+1.2*wheel_link_radius} ${body_link_y_dim/2+wheel_link_length/2} ${wheel_link_z_location}" rpy="0 0 0" />
	<axis xyz="0 1 0"/>
	<limit effort="1000" velocity="1000"/>
	<dynamics damping="1.0" friction="1.0"/>
</joint>

<link name="wheel2_link">
	<visual>
		<origin rpy="1.570795 0 0" xyz="0 0 0"/>
		<geometry>
			<cylinder length="${wheel_link_length}" radius="${wheel_link_radius}"/>
		</geometry>
	</visual>
	
	<collision>
		<origin rpy="1.570795 0 0" xyz="0 0 0"/>
		<geometry>
			<cylinder length="${wheel_link_length}" radius="${wheel_link_radius}"/>	
		</geometry>
	</collision>
	<xacro:inertia_wheel />
</link>

<!-- ################################################# -->
<!-- END: back left wheel of the robot and the joint -->
<!-- ################################################# -->



<!-- ################################################# -->
<!-- START: front rigth wheel of the robot and the joint -->
<!-- ################################################# -->
<joint name="wheel3_joint" type="continuous" >
	<parent link="body_link"/>
	<child  link="wheel3_link" />
	<origin xyz="${body_link_x_dim/2-1.2*wheel_link_radius} ${-body_link_y_dim/2-wheel_link_length/2} ${wheel_link_z_location}" rpy="0 0 0" />
	<axis xyz="0 1 0"/>
	<limit effort="1000" velocity="1000"/>
	<dynamics damping="1.0" friction="1.0"/>
</joint>

<link name="wheel3_link">
	<visual>
		<origin rpy="1.570795 0 0" xyz="0 0 0"/>
		<geometry>
			<cylinder length="${wheel_link_length}" radius="${wheel_link_radius}"/>
		</geometry>
	</visual>
	<collision>
		<origin rpy="1.570795 0 0" xyz="0 0 0"/>
		<geometry>
			<cylinder length="${wheel_link_length}" radius="${wheel_link_radius}"/>	
		</geometry>
	</collision>
	<xacro:inertia_wheel />
</link>

<!-- ################################################# -->
<!-- END: front right wheel of the robot and the joint -->
<!-- ################################################# -->


<!-- ################################################# -->
<!-- START: front left wheel of the robot and the joint -->
<!-- ################################################# -->
<joint name="wheel4_joint" type="continuous" >
	<parent link="body_link"/>
	<child  link="wheel4_link" />
	<origin xyz="${body_link_x_dim/2-1.2*wheel_link_radius} ${body_link_y_dim/2+wheel_link_length/2} ${wheel_link_z_location}" rpy="0 0 0" />
	<axis xyz="0 1 0"/>
	<limit effort="1000" velocity="1000"/>
	<dynamics damping="1.0" friction="1.0"/>
</joint>

<link name="wheel4_link">
	<visual>
		<origin rpy="1.570795 0 0" xyz="0 0 0"/>
		<geometry>
			<cylinder length="${wheel_link_length}" radius="${wheel_link_radius}"/>
		</geometry>
	</visual>
	<collision>
		<origin rpy="1.570795 0 0" xyz="0 0 0"/>
		<geometry>
			<cylinder length="${wheel_link_length}" radius="${wheel_link_radius}"/>	
		</geometry>
	</collision>
	<xacro:inertia_wheel />
</link>

<!-- ################################################# -->
<!-- END: front left wheel of the robot and the joint -->
<!-- ################################################# -->



</robot>
